<?xml version="1.0" encoding="utf-8" ?>
<!-- =================================================================================== -->
<!-- |    This document was autogenerated by xacro from /home/zhitao/diskE/Project/homework1_summation/hw3_space_ws/src/mrobot_description/urdf/robot.xacro | -->
<!-- |    EDITING THIS FILE BY HAND IS NOT RECOMMENDED                                 | -->
<!-- =================================================================================== -->
<!-- This URDF was automatically created by SolidWorks to URDF Exporter! Originally created by Stephen Brawner (brawner@gmail.com) 
     Commit Version: 1.6.0-4-g7f85cfe  Build Version: 1.6.7995.38578
     For more information, please see http://wiki.ros.org/sw_urdf_exporter -->
<robot name="mrobot">
    <link name="base_link">
        
<inertial>
            <origin rpy="0 0 0" xyz="-0.00250187055399557 -4.16333634234434E-17 0.102093304789128" />
            <mass value="6.94149844484666" />
            <inertia ixx="0.0520196309505746" ixy="1.68127167273141E-18" ixz="-2.90897863231171E-05" iyy="0.0509630023046414" iyz="1.79335938951065E-18" izz="0.0509538546030715" />
        </inertial>

        <visual>
            <origin rpy="0 0 0" xyz="0 0 0" />
            <geometry>
                <mesh filename="package://mrobot_description/meshes/base_link.STL" />
            </geometry>
            <material name="">
                <color rgba="0.792156862745098 0.819607843137255 0.933333333333333 1" />
            </material>
        </visual>
        <collision>
            <origin rpy="0 0 0" xyz="0 0 0" />
            <geometry>
                <mesh filename="package://mrobot_description/meshes/base_link.STL" />
            </geometry>
        </collision>
    </link>
    <link name="link3_propeller_r">
        
<inertial>
            <origin rpy="0 0 0" xyz="0.0358547056389072 1.57481043736724E-07 0.0376222388867364" />
            <mass value="0.0232842042460977" />
            <inertia ixx="1.91884886962561E-05" ixy="-5.96973777799785E-11" ixz="-1.65633553759101E-05" iyy="3.63752103759262E-05" iyz="2.27699860606211E-11" izz="2.02836536909938E-05" />
        </inertial>

        <visual>
            <origin rpy="0 0 0" xyz="0 0 0" />
            <geometry>
                <mesh filename="package://mrobot_description/meshes/link3_propeller_r.STL" />
            </geometry>
            <material name="">
                <color rgba="1 1 1 1" />
            </material>
        </visual>
        <collision>
            <origin rpy="0 0 0" xyz="0 0 0" />
            <geometry>
                <mesh filename="package://mrobot_description/meshes/link3_propeller_r.STL" />
            </geometry>
        </collision>
    </link>
    <joint name="joint3_propeller_r" type="revolute">
        <origin rpy="3.1416 0 -1.5708" xyz="0.03 -0.21 0.19" />
        <parent link="base_link" />
        <child link="link3_propeller_r" />
        <axis xyz="0 0 -1" />
        <limit effort="4" lower="-4" upper="4" velocity="4" />
    </joint>
    <link name="link2_propeller_r">
        
<inertial>
            <origin rpy="0 0 0" xyz="-0.000547980281035122 5.94447525786856E-08 -0.0309642074433607" />
            <mass value="0.0217803101754596" />
            <inertia ixx="1.92811006991552E-05" ixy="7.44325461979967E-12" ixz="-2.86922802348169E-07" iyy="2.04243309946027E-05" iyz="7.14397664513597E-12" izz="2.09913107838725E-06" />
        </inertial>

        <visual>
            <origin rpy="0 0 0" xyz="0 0 0" />
            <geometry>
                <mesh filename="package://mrobot_description/meshes/link2_propeller_r.STL" />
            </geometry>
            <material name="">
                <color rgba="1 1 1 1" />
            </material>
        </visual>
        <collision>
            <origin rpy="0 0 0" xyz="0 0 0" />
            <geometry>
                <mesh filename="package://mrobot_description/meshes/link2_propeller_r.STL" />
            </geometry>
        </collision>
    </link>
    <joint name="joint2_propeller_r" type="revolute">
        <origin rpy="-1.5708 0 -1.5708" xyz="0.055 0 0.09" />
        <parent link="link3_propeller_r" />
        <child link="link2_propeller_r" />
        <axis xyz="0 0 -1" />
        <limit effort="4" lower="-4" upper="4" velocity="4" />
    </joint>
    <link name="link1_propeller_r">
        
<inertial>
            <origin rpy="0 0 0" xyz="-5.55111512312578E-17 2.08166817117217E-17 0.039" />
            <mass value="0.00319261117037718" />
            <inertia ixx="1.34136270464279E-06" ixy="-1.68021061924834E-21" ixz="2.64088781292146E-24" iyy="1.34136270464278E-06" iyz="-6.36026356399289E-24" izz="2.68059700183865E-06" />
        </inertial>

        <visual>
            <origin rpy="0 0 0" xyz="0 0 0" />
            <geometry>
                <mesh filename="package://mrobot_description/meshes/link1_propeller_r.STL" />
            </geometry>
            <material name="">
                <color rgba="1 1 1 1" />
            </material>
        </visual>
        <collision>
            <origin rpy="0 0 0" xyz="0 0 0" />
            <geometry>
                <mesh filename="package://mrobot_description/meshes/link1_propeller_r.STL" />
            </geometry>
        </collision>
    </link>
    <joint name="joint1_propeller_r" type="revolute">
        <origin rpy="0 1.5708 0" xyz="-0.02 0 -0.055" />
        <parent link="link2_propeller_r" />
        <child link="link1_propeller_r" />
        <axis xyz="0 0 -1" />
        <limit effort="1000" lower="-10000" upper="10000" velocity="500" />
    </joint>
    <link name="link3_propeller_l">
        
<inertial>
            <origin rpy="0 0 0" xyz="-0.0358547056389073 -1.57481043736724E-07 0.0376222388867364" />
            <mass value="0.0232842042460978" />
            <inertia ixx="1.91884886962561E-05" ixy="-5.96973777997515E-11" ixz="1.65633553759101E-05" iyy="3.63752103759263E-05" iyz="-2.27699860483845E-11" izz="2.02836536909938E-05" />
        </inertial>

        <visual>
            <origin rpy="0 0 0" xyz="0 0 0" />
            <geometry>
                <mesh filename="package://mrobot_description/meshes/link3_propeller_l.STL" />
            </geometry>
            <material name="">
                <color rgba="1 1 1 1" />
            </material>
        </visual>
        <collision>
            <origin rpy="0 0 0" xyz="0 0 0" />
            <geometry>
                <mesh filename="package://mrobot_description/meshes/link3_propeller_l.STL" />
            </geometry>
        </collision>
    </link>
    <joint name="joint3_propeller_l" type="revolute">
        <origin rpy="3.1416 0 -1.5708" xyz="0.03 0.21 0.19" />
        <parent link="base_link" />
        <child link="link3_propeller_l" />
        <axis xyz="0 0 -1" />
        <limit effort="4" lower="-4" upper="4" velocity="4" />
    </joint>
    <link name="link2_propeller_l">
        
<inertial>
            <origin rpy="0 0 0" xyz="0.000547980281035115 -5.94447525856245E-08 -0.0309642074433607" />
            <mass value="0.0217803101754596" />
            <inertia ixx="1.92811006991551E-05" ixy="7.44325462014238E-12" ixz="2.86922802348166E-07" iyy="2.04243309946027E-05" iyz="-7.14397664563089E-12" izz="2.09913107838725E-06" />
        </inertial>

        <visual>
            <origin rpy="0 0 0" xyz="0 0 0" />
            <geometry>
                <mesh filename="package://mrobot_description/meshes/link2_propeller_l.STL" />
            </geometry>
            <material name="">
                <color rgba="1 1 1 1" />
            </material>
        </visual>
        <collision>
            <origin rpy="0 0 0" xyz="0 0 0" />
            <geometry>
                <mesh filename="package://mrobot_description/meshes/link2_propeller_l.STL" />
            </geometry>
        </collision>
    </link>
    <joint name="joint2_propeller_l" type="revolute">
        <origin rpy="-1.5708 0 1.5708" xyz="-0.055 0 0.09" />
        <parent link="link3_propeller_l" />
        <child link="link2_propeller_l" />
        <axis xyz="0 0 -1" />
        <limit effort="4" lower="-4" upper="4" velocity="4" />
    </joint>
    <link name="link1_propeller_l">
        
<inertial>
            <origin rpy="0 0 0" xyz="-1.38777878078145E-17 2.42861286636753E-17 0.039" />
            <mass value="0.00319261117037719" />
            <inertia ixx="1.34136270464279E-06" ixy="-4.74336382510877E-21" ixz="-5.09025213552507E-22" iyy="1.34136270464278E-06" iyz="-5.05235365206194E-24" izz="2.68059700183865E-06" />
        </inertial>

        <visual>
            <origin rpy="0 0 0" xyz="0 0 0" />
            <geometry>
                <mesh filename="package://mrobot_description/meshes/link1_propeller_l.STL" />
            </geometry>
            <material name="">
                <color rgba="1 1 1 1" />
            </material>
        </visual>
        <collision>
            <origin rpy="0 0 0" xyz="0 0 0" />
            <geometry>
                <mesh filename="package://mrobot_description/meshes/link1_propeller_l.STL" />
            </geometry>
        </collision>
    </link>
    <joint name="joint1_propeller_l" type="revolute">
        <origin rpy="3.1416 -1.5708 0" xyz="-0.03 0 -0.055" />
        <parent link="link2_propeller_l" />
        <child link="link1_propeller_l" />
        <axis xyz="0 -0.011659 -0.99993" />
        <limit effort="1000" lower="-10000" upper="10000" velocity="500" />
    </joint>
    <link name="link1_b">
        
<inertial>
            <origin rpy="0 0 0" xyz="-0.14556481495406 -6.20150917424178E-08 0.0195495186334518" />
            <mass value="0.0264925100332698" />
            <inertia ixx="2.33590742680818E-06" ixy="-2.34168552246384E-11" ixz="-4.11034457388889E-07" iyy="3.38737961647893E-05" iyz="-9.44647937670339E-12" izz="3.27294154174667E-05" />
        </inertial>

        <visual>
            <origin rpy="0 0 0" xyz="0 0 0" />
            <geometry>
                <mesh filename="package://mrobot_description/meshes/link1_b.STL" />
            </geometry>
            <material name="">
                <color rgba="1 1 1 1" />
            </material>
        </visual>
        <collision>
            <origin rpy="0 0 0" xyz="0 0 0" />
            <geometry>
                <mesh filename="package://mrobot_description/meshes/link1_b.STL" />
            </geometry>
        </collision>
    </link>
    <joint name="joint1_b" type="fixed">
        <origin rpy="0 0 0" xyz="0 0 0" />
        <parent link="base_link" />
        <child link="link1_b" />
        <axis xyz="0 0 0" />
        <limit effort="4" lower="-4" upper="4" velocity="4" />
    </joint>
    <link name="link_b">
        
<inertial>
            <origin rpy="0 0 0" xyz="1.38777878078145E-17 2.77555756156289E-17 0.039" />
            <mass value="0.00319261117037719" />
            <inertia ixx="1.34136270464279E-06" ixy="4.38147230711682E-21" ixz="2.16313585702643E-22" iyy="1.34136270464278E-06" iyz="1.80899528309417E-22" izz="2.68059700183865E-06" />
        </inertial>

        <visual>
            <origin rpy="0 0 0" xyz="0 0 0" />
            <geometry>
                <mesh filename="package://mrobot_description/meshes/link_b.STL" />
            </geometry>
            <material name="">
                <color rgba="1 1 1 1" />
            </material>
        </visual>
        <collision>
            <origin rpy="0 0 0" xyz="0 0 0" />
            <geometry>
                <mesh filename="package://mrobot_description/meshes/link_b.STL" />
            </geometry>
        </collision>
    </link>
    <joint name="joint_b" type="revolute">
        <origin rpy="0 0 1.5708" xyz="-0.18 0 0" />
        <parent link="link1_b" />
        <child link="link_b" />
        <axis xyz="0 0 -1" />
        <limit effort="1000" lower="-10000" upper="10000" velocity="500" />
    </joint>


    <gazebo reference="base_link">
        <material>Gazebo/Grey</material>
    </gazebo>

    <gazebo reference="link3_propeller_r">
        <material>Gazebo/Red</material>
    </gazebo>

    <gazebo reference="link3_propeller_l">
        <material>Gazebo/Red</material>
    </gazebo>

    <gazebo reference="base_link">
        <turnGravityOff>true</turnGravityOff>
    </gazebo>

    <gazebo reference="link3_propeller_r">
        <turnGravityOff>true</turnGravityOff>
    </gazebo>

    <gazebo reference="link2_propeller_r">
        <turnGravityOff>true</turnGravityOff>
    </gazebo>

    <gazebo reference="link1_propeller_r">
        <turnGravityOff>true</turnGravityOff>
    </gazebo>

    <gazebo reference="link3_propeller_l">
        <turnGravityOff>true</turnGravityOff>
    </gazebo>

    <gazebo reference="link2_propeller_l">
        <turnGravityOff>true</turnGravityOff>
    </gazebo>

    <gazebo reference="link1_propeller_l">
        <turnGravityOff>true</turnGravityOff>
    </gazebo>

    <gazebo reference="link1_b">
        <turnGravityOff>true</turnGravityOff>
    </gazebo>

    <gazebo reference="link_b">
        <turnGravityOff>true</turnGravityOff>
    </gazebo>


<transmission name="trans_joint3_propeller_r">
        <type>transmission_interface/SimpleTransmission</type>
        <joint name="joint3_propeller_r">
            <hardwareInterface>hardware_interface/PositionJointInterface</hardwareInterface>
        </joint>
        <actuator name="joint3_propeller_r_motor">
            <hardwareInterface>hardware_interface/PositionJointInterface</hardwareInterface>
            <mechanicalReduction>1</mechanicalReduction>
        </actuator>
    </transmission>
    <transmission name="trans_joint2_propeller_r">
        <type>transmission_interface/SimpleTransmission</type>
        <joint name="joint2_propeller_r">
            <hardwareInterface>hardware_interface/PositionJointInterface</hardwareInterface>
        </joint>
        <actuator name="joint2_propeller_r_motor">
            <hardwareInterface>hardware_interface/PositionJointInterface</hardwareInterface>
            <mechanicalReduction>1</mechanicalReduction>
        </actuator>
    </transmission>
    <transmission name="trans_joint1_propeller_r">
        <type>transmission_interface/SimpleTransmission</type>
        <joint name="joint1_propeller_r">
            <hardwareInterface>hardware_interface/PositionJointInterface</hardwareInterface>
        </joint>
        <actuator name="joint1_propeller_r_motor">
            <hardwareInterface>hardware_interface/PositionJointInterface</hardwareInterface>
            <mechanicalReduction>1</mechanicalReduction>
        </actuator>
    </transmission>
    <transmission name="trans_joint3_propeller_l">
        <type>transmission_interface/SimpleTransmission</type>
        <joint name="joint3_propeller_l">
            <hardwareInterface>hardware_interface/PositionJointInterface</hardwareInterface>
        </joint>
        <actuator name="joint3_propeller_l_motor">
            <hardwareInterface>hardware_interface/PositionJointInterface</hardwareInterface>
            <mechanicalReduction>1</mechanicalReduction>
        </actuator>
    </transmission>
    <transmission name="trans_joint2_propeller_l">
        <type>transmission_interface/SimpleTransmission</type>
        <joint name="joint2_propeller_l">
            <hardwareInterface>hardware_interface/PositionJointInterface</hardwareInterface>
        </joint>
        <actuator name="joint2_propeller_l_motor">
            <hardwareInterface>hardware_interface/PositionJointInterface</hardwareInterface>
            <mechanicalReduction>1</mechanicalReduction>
        </actuator>
    </transmission>
    <transmission name="trans_joint1_propeller_l">
        <type>transmission_interface/SimpleTransmission</type>
        <joint name="joint1_propeller_l">
            <hardwareInterface>hardware_interface/PositionJointInterface</hardwareInterface>
        </joint>
        <actuator name="joint1_propeller_l_motor">
            <hardwareInterface>hardware_interface/PositionJointInterface</hardwareInterface>
            <mechanicalReduction>1</mechanicalReduction>
        </actuator>
    </transmission>
    <transmission name="trans_joint_b">
        <type>transmission_interface/SimpleTransmission</type>
        <joint name="joint_b">
            <hardwareInterface>hardware_interface/PositionJointInterface</hardwareInterface>
        </joint>
        <actuator name="joint_b_motor">
            <hardwareInterface>hardware_interface/PositionJointInterface</hardwareInterface>
            <mechanicalReduction>1</mechanicalReduction>
        </actuator>
    </transmission>
    <gazebo>
        <plugin name="gazebo_ros_control" filename="libgazebo_ros_control.so">
            <robotNamespace>/</robotNamespace>
        </plugin>
    </gazebo>
</robot>